Workbook

Sheet Summary
A1: MATARA OT RENOVATION - CONSOLIDATED BOQ & ENGINEER'S PRELIMINARY ESTIMATE – REV 7
A2: Updated with reviewed Electrical and Ancillary Works BOQs. Site Works, MVAC and Rainwater packages have been adjusted to remove identified overlaps. Original source sheets are retained where applicable for audit; reviewed package sheets govern this consolidated estimate.
A4: Package / Section | B4: Reviewed Direct / Base Amount (LKR) | C4: Contingency (LKR) | D4: VAT / Tax (LKR) | E4: Consolidated Total (LKR) | F4: Status / Review Note
A5: A. Site Works / Landscaping – REVIEWED | B5: ='Site Works - Reviewed'!J39 -> 8984311 | C5: ='Site Works - Reviewed'!J41 -> 898431.1 | D5: 0 | E5: ='Site Works - Reviewed'!J42 -> 9882742.1 | F5: Detailed Site Works re-totalled; clear duplicate items removed. Original source sheet retained.
A6: B. Modular Operating Theatre Package | B6: 1.4860536e+08 | C6: 14860536 | D6: 29423862 | E6: 1.9288976e+08 | F6: UNCHANGED specialist package; electrical interfaces reconciled against reviewed Electrical BOQ.
A7: C. Added Renovation Works incl. Equipment Relocation & MEP Strip-out | B7: ='Added Renovation BOQ'!G100 -> 76810177 | C7: 6252222.6 | D7: 12379401 | E7: 81153849 | F7: Existing preliminary renovation estimate retained.
A8: D. MVAC Works – REVIEWED | B8: ='MVAC BOQ & Estimate'!G31 -> 98100000 | C8: ='MVAC BOQ & Estimate'!#REF! -> #REF! | D8: 0 | E8: ='MVAC BOQ & Estimate'!#REF! -> #REF! | F8: Electrical allowance reduced because DB-AC and power feeders/cables are now in Electrical BOQ.
A9: E. Medical Gas System | B9: ='Medical Gas BOQ & Estimate'!G30 -> 40525000 | C9: ='Medical Gas BOQ & Estimate'!#REF! -> #REF! | D9: 0 | E9: ='Medical Gas BOQ & Estimate'!#REF! -> #REF! | F9: Preliminary specialist estimate; Modular OT terminal hardware excluded.
A10: F. Water Supply System | B10: ='Water Supply BOQ & Estimate'!G32 -> 7038560 | C10: ='Water Supply BOQ & Estimate'!#REF! -> #REF! | D10: 0 | E10: ='Water Supply BOQ & Estimate'!#REF! -> #REF! | F10: Preliminary specialist estimate; sanitary fixtures excluded where already measured.
A11: G. Wastewater & Sewerage System | B11: ='Wastewater & Sewer BOQ'!G30 -> 5632000 | C11: ='Wastewater & Sewer BOQ'!G32 -> 563200 | D11: 0 | E11: ='Wastewater & Sewer BOQ'!G33 -> 6195200 | F11: Preliminary specialist estimate; foul drainage only.
A12: H. Rainwater Disposal System – REVIEWED | B12: ='Rainwater Disposal BOQ'!G24 -> 3479000 | C12: ='Rainwater Disposal BOQ'!#REF! -> #REF! | D12: 0 | E12: ='Rainwater Disposal BOQ'!#REF! -> #REF! | F12: Courtyard diversion retained; general roof gutters/downpipes removed because Ancillary Roof BOQ includes them.
A13: I. Electrical Installation – REVIEWED | B13: ='Electrical BOQ - Reviewed'!K54 -> 18731600 | C13: ='Electrical BOQ - Reviewed'!K56 -> 1873160 | D13: 0 | E13: ='Electrical BOQ - Reviewed'!K57 -> 20604760 | F13: Source LKR 21.0396m less LKR 2.308m identified Modular OT overlaps.
A14: J. Ancillary Buildings & Extension – REVIEWED | B14: ='Ancillary Works - Reviewed'!H65 -> 15503821 | D14: 0 | F14: Detailed source line items used; stale subtotals and roof amount errors corrected in reviewed sheet.
A16: PROJECT TOTAL | B16: =SUM(B5:B14) -> 4.2340983e+08 | D16: =SUM(D5:D14) -> 41803262 | F16: VAT/tax is carried only where already included in the earlier Modular OT and Added Renovation package estimates; newly reviewed/additional packages are shown excluding VAT.
A18: Key Consolidation Controls / Findings | B18: Value | D18: Source / Cross-check | E18: Reference | F18: Consolidation Treatment
A19: Electrical source subtotal | B19: LKR 21,039,600 | D19: Uploaded Mathara Hospital BOQ(1).xls | E19: Electrical source | F19: Reviewed line by line
A20: Electrical duplicate deduction | B20: LKR 2,308,000 | D20: Modular OT C6/E2 vs Electrical lighting/socket quantities | E20: Electrical Reconciliation | F20: 40 OT lights/points and 80 OT sockets removed from Electrical
A21: MVAC electrical overlap | B21: LKR 4,000,000 direct reduction | D21: Electrical DB-AC/cables now detailed in source Electrical BOQ | E21: MVAC E2 | F21: MVAC E2 reduced from LKR 5.0m to LKR 1.0m interface-only
A22: Site Works source detailed direct subtotal | B22: LKR 9,176,793 | D22: Site Works - Unchanged | E22: Detailed rows | F22: Old consolidated Summary had been carrying an outdated lower source amount
A23: Site Works reviewed direct subtotal | B23: LKR 8,984,311 | D23: Site Works - Reviewed | E23: Duplicate removal register | F23: Canopy roof, hardstanding overlap, excess disposal and duplicate landscape maintenance adjusted
A24: Ancillary reviewed direct subtotal | B24: ='Ancillary Works - Reviewed'!#REF! -> #REF! | D24: Uploaded BOQ_Ancilary Building and extension.xlsx | E24: Ancillary Works - Reviewed | F24: Detailed line items govern; stale summary ignored
A25: Ancillary roof schedule | B25: Qty × Rate recalculated | D25: Source Sheet1 | E25: R.02-R.15 | F25: Stored amounts were inconsistent with current displayed quantities/rates
A26: Rainwater roof drainage overlap | B26: LKR 357,000 direct removed | D26: Ancillary Roof R.08-R.12 vs Rainwater D1-D4 | E26: Rainwater Reconciliation | F26: Courtyard diversion remains; general roof drainage governed by Ancillary BOQ
A27: Estimate status | B27: Preliminary / Budgetary | D27: All reviewed packages | E27: Rev 7 | F27: Final tender requires coordinated drawings, remeasurement and supplier quotations for specialist items

Sheet Added Renovation BOQ
A1: ADDED PREPARATORY / DEMOLITION / CIVIL RENOVATION BOQ & ESTIMATE
A2: Project: Improvement to MEP Services and Renovation of Theatre Complex at District General Hospital Matara | I2: Contingency | J2: 0.1
A3: Section | B3: Item No. | C3: Description | D3: Unit | E3: Qty | F3: Rate (LKR) | G3: Amount (LKR) | H3: Rate Type | I3: Rate Ref. | J3: Drawing / Basis | K3: Remarks / Qualification
A4: A - Preparatory / Enabling Works
A5: A | B5: A1 | C5: Prepare renovation phasing, infection-control/dust/noise control plans, permits, demolition method statements and coordination submissions for work in/adjacent to the occupied hospital. | D5: LS | E5: 1 | F5: 150000 | G5: =E5*F5 -> 150000 | H5: Engineer PS | I5: PS-A1 | J5: Hospital renovation / ICRA basis | K5: Excludes specialist OT validation already in modular package.
A6: A | B6: A2 | C6: Provide and maintain dust-tight temporary partitions/hoardings, zipped/controlled access, local negative-air/dust extraction arrangements and sealed interfaces as required for phased internal demolition. | D6: LS | E6: 1 | F6: 500000 | G6: =E6*F6 -> 500000 | H6: Engineer PS | I6: PS-A2 | J6: Hospital operational constraint | K6: Final arrangement to infection-control approval; power to temporary equipment by relevant trade.
A7: A | B7: A3 | C7: Protect retained floors, walls, doors, lifts, adjacent equipment and operational routes; provide temporary floor/wall protection and reinstate after completion. | D7: LS | E7: 1 | F7: 50000 | G7: =E7*F7 -> 50000 | H7: Engineer PS | I7: PS-A3 | J7: Existing plans / hospital constraint | K7: Protection for internal renovation only; site-work protection remains in unchanged Site Works BOQ.
A8: A | B8: A4 | C8: Detailed measured survey, setting-out, service detection/scanning and marking of existing structure/services before demolition; maintain survey records and coordinate revised shop drawings. | D8: LS | E8: 1 | F8: 450000 | G8: =E8*F8 -> 450000 | H8: Engineer PS | I8: PS-A4 | J8: Drawings 004/005/006/007 | K8: Includes verification of slab/beam positions and service routes before cutting.
A9: A | B9: A5 | C9: Temporary internal debris route, controlled material handling, daily hospital-sensitive housekeeping and progressive cleaning during demolition and civil works. | D9: LS | E9: 1 | F9: 600000 | G9: =E9*F9 -> 600000 | H9: Engineer PS | I9: PS-A5 | J9: Hospital operational constraint | K9: Separate from final terminal clean.
A10: A | B10: A6 | C10: Prepare existing structural slab/substrate in four OTs and scrub rooms by inspection, grinding and local patch repair before modular flooring installation; exclude self-levelling screed, conductive vinyl, copper grid and coving included in unchanged Modular OT BOQ. | D10: m² | E10: 220 | F10: 1500 | G10: =E10*F10 -> 330000 | H10: Engineer PS | I10: PS-A6 | J10: OT + scrub measured area ≈219.989 m² | K10: Only substrate repair/preparation prior to specialist modular flooring.
A11: A | B11: A7 | C11: Prepare structural slab/wall interfaces for modular OT support fixings: survey/mark anchors, remove loose finishes and locally repair concrete; exclude modular secondary steel/support frames and specialist penetrations already in modular package. | D11: LS | E11: 1 | F11: 500000 | G11: =E11*F11 -> 500000 | H11: Engineer PS | I11: PS-A7 | J11: Modular OT interface | K11: No double payment for modular support frames.
A12: A | B12: A8 | C12: Final pre-installation builders' clean and dust removal of OT/scrub structural shell immediately before specialist modular theatre installation. | D12: LS | E12: 1 | F12: 400000 | G12: =E12*F12 -> 400000 | H12: Engineer PS | I12: PS-A8 | J12: Modular OT preparatory work | K12: Not the final cleanroom/OT validation or terminal clean.
A13: Subtotal - A - Preparatory / Enabling Works | G13: =SUM(G5:G12) -> 2980000
A14: B - Demolition & Strip-out
A15: B | B15: B1 | C15: Carefully dismantle existing aluminium door/window assemblies including frames, glazing and fittings; stack reusable materials and make good disturbed jambs/sills. | D15: m² | E15: 220 | F15: 405 | G15: =E15*F15 -> 89100 | H15: Matara BSR 2026 | I15: DM41 | J15: Drawing 006 / existing openings | K15: Preliminary combined area; remeasure by opening schedule.
A16: B | B16: B2 | C16: Carefully remove aluminium glazed partition / curtain-wall type assemblies including mullions, transoms, glazing and sealants; stack/dispose as directed and make good fixing locations. | D16: m² | E16: 70 | F16: 369 | G16: =E16*F16 -> 25830 | H16: Matara BSR 2026 - qualified | I16: DM43 | J16: Drawing 006 | K16: Closest BSR proxy for aluminium partition removal; specialist glass handling may require adjustment.
B17: B3 | C17: Carefully dismantle existing wooden door including frames, slashes ,glazing and fittings; stack reusable materials and make good disturbed jambs/sills. | D17: m2 | E17: 60 | F17: =1000 -> 1000 | G17: =E17*F17 -> 60000
A18: B | B18: B4 | C18: Demolish non-load-bearing brick/block partition walls including finishes; controlled cutting, dust suppression, protection of structure/services and clearing debris. | D18: m³ | E18: 70 | F18: 2000 | G18: =E18*F18 -> 140000 | H18: Matara BSR 2026 - qualified | I18: DM08 | J18: Drawing 006 red demolition | K18: Quantity assumes predominantly 100/150 mm partitions; verify wall thicknesses.
A19: B | B19: B5 | C19: Demolish any load-bearing masonry only where specifically instructed after structural approval, including controlled sequence; masonry demolition rate only. | D19: m³ | E19: 10 | F19: 2000 | G19: =E19*F19 -> 20000 | H19: Matara BSR 2026 - qualified | I19: DM08 | J19: Drawing 005/006 | K19: ZERO provisional quantity. Temporary propping/needling priced separately under C7.
A20: B | B20: B6 | C20: Remove existing floor tiles and tile-bed/screed finishes to areas receiving new finishes, protect structural slab and prepare exposed surface. | D20: m² | E20: 800 | F20: 770 | G20: =E20*F20 -> 616000 | H20: Matara BSR 2026 | I20: DM19 | J20: Drawings 006/007 + finish renewal allowance | K20: Preliminary internal renovation floor-strip area.
B21: B7 | C21: Cut /remove existing floor concrete without damaging the reinforcement if any; up to a maximum of 150mm depth for wall foundation rate to included removal of debris | D21: m3 | E21: 2 | F21: 30000 | G21: =E21*F21 -> 60000 | H21: Engineer PS
A22: B | B22: B8 | C22: Carefully dismantle and remove existing lightweight canopy roof covering, including corrugated roofing sheets, frames, ridge/flashing pieces, gutters where affected, screws, bolts and other fixings; lower materials safely, segregate reusable materials if directed, load and transport debris to an approved disposal location, complete. | D22: m² | E22: 45 | F22: 650 | G22: =E22*F22 -> 29250 | H22: Derived from BSR | I22: PS-B6 | J22: Drawing 009 ceiling layout | K22: MEP disconnection/removal above ceilings is measured separately under Section I; protect all live services to remain.
B23: B9 | C23: Carefully remove existing timber trolley/wall guard fixed to walls, including removal of timber sections, brackets, screws, nails and other fixings; cutting where necessary; making good minor holes/damaged plaster surfaces caused by removal; lowering, loading, transporting and disposing of debris/materials to an approved disposal location, complete as directed by the Engineer. | D23: m | E23: 50 | F23: 690 | G23: =E23*F23 -> 34500
A24: B | B24: B10 | C24: Remove existing wall tiles, splashbacks and bonded wall finishes where required for new wet-area/hygienic finishes, including surface preparation. | D24: m² | E24: 200 | F24: 650 | G24: =E24*F24 -> 130000 | H24: Engineer PS | I24: PS-B7 | J24: Wet rooms / equipment washing / accessible WC | K24: Actual finish build-up to be verified before demolition.
A25: B | B25: B11 | C25: Carefully remove existing sanitary fixtures, counters and minor fixed non-medical fittings affected by renovation; cap openings by relevant MEP trade and store/dispose as directed. | D25: Nr | E25: 15 | F25: 6500 | G25: =E25*F25 -> 97500 | H25: Engineer PS | I25: PS-B8 | J25: Room layout / wet areas | K25: Medical equipment relocation is measured separately under Section I; sanitary fixture removal remains under this item.
B26: B12 | C26: Demolishing reinforced cement concrete in suspended floors up to 100mm-150mm thick , removing reinforcement and clearing debris. | D26: m3 | E26: 20 | F26: 22344 | G26: =E26*F26 -> 446880
B27: B13 | C27: Demolishing cement concrete and clearing debris in floors from 100mm to 150mm thick floors. | D27: m3 | E27: 40 | F27: 10209 | G27: =E27*F27 -> 408360
A28: B | B28: B14 | C28: Load, cart and dispose demolition/strip-out debris by tractor trailer to approved disposal point up to 3 km, including fees/attendance. | D28: Load | E28: 45 | F28: 4207 | G28: =E28*F28 -> 189315 | H28: Existing Site BOQ BSR | I28: B40 | J28: Disposal allowance | K28: Preliminary load count; hazardous material disposal excluded.
A29: Subtotal - B - Demolition & Strip-out | G29: =SUM(G15:G28) -> 2346735
A30: C - Structural / Builders' Work
A31: C | B31: C1 | C31: Saw-cut and form new openings in non-load-bearing walls for doors, transfer openings and coordinated services; provide neat edges and making good. | D31: m2 | E31: 75 | F31: 5000 | G31: =E31*F31 -> 375000 | H31: Engineer PS | I31: PS-C1 | J31: Drawings 007/008 | K31: Excludes structural beam/slab openings unless Engineer-approved.
A32: C | B32: C2 | C32: Grade 25 concrete to local slab infills, upstands, small equipment plinths, thresholds and builders-work bases; reinforcement/formwork separate. | D32: m³ | E32: 12 | F32: 32300 | G32: =E32*F32 -> 387600 | H32: Matara BSR 2026 | I32: CT54 | J32: New construction / local making good | K32: Final member sizes/details to Engineer approval.
B33: C3 | C33: Grade 25 concrete to stiffner columns; reinforcement/formwork separate. | D33: m³ | E33: 3 | F33: 34300 | G33: =E33*F33 -> 102900
A34: C | B34: C4 | C34: High-yield/mild steel reinforcement to local concrete works, cut, bend and fix including binding wire. | D34: kg | E34: 1500 | F34: 494 | G34: =E34*F34 -> 741000 | H34: Matara BSR 2026 - qualified | I34: RF02 | J34: Local structural works | K34: Split by bar grade/level if final BSR requires.
A35: C | B35: C5 | C35: Plywood formwork to local beams, trimming/upstands/plinths and concrete repairs, including props, ties and striking. | D35: m² | E35: 50 | F35: 4070 | G35: =E35*F35 -> 203500 | H35: Matara BSR 2026 - qualified | I35: FW19 | J35: Local structural works | K35: Budgetary proxy; final formwork category to actual member.
A36: C | B36: C6 | C36: Pre-cast lintels size 225 mm × 225 mm deep in Grade 25 concrete, reinforced with 4 nos. of 12mm dia. tor steel bars and 6mm mild steel stirrups @ 150mm c/c, including necessary formwork on the ground floor. | D36: m | E36: 45 | F36: 5650 | G36: =E36*F36 -> 254250 | H36: Derived Matara BSR 2026 | I36: DER-L100 | J36: New door openings | K36: Final lintel size/reinforcement to approved details.
A37: C | B37: C7 | C37: Pre-cast lintels size 225 mm × 150 mm deep in Grade 25 concrete, reinforced with 4 nos. of 10 mm dia. tor steel bars and 6mm mild steel stirrups @ 150mm c/c, including necessary formwork on the ground floor. | D37: m | E37: 12 | F37: 3800 | G37: =E37*F37 -> 45600 | H37: Derived Matara BSR 2026 | I37: DER-L150 | J37: New door openings | K37: Final lintel size/reinforcement to approved details.
A38: C | B38: C8 | C38: Pre-cast lintels size 150 mm × 150 mm deep in Grade 25 concrete, reinforced with 4 nos. of 10 mm dia. tor steel bars and 6mm mild steel stirrups @ 150mm c/c, including necessary formwork on the ground floor. | D38: m | E38: 14 | F38: =F37/225*150 -> 2533.3333 | G38: =E38*F38 -> 35466.667 | H38: Derived Matara BSR 2026 | I38: DER-L150 | J38: New door openings | K38: Final lintel size/reinforcement to approved details.
A39: C | B39: C9 | C39: Temporary shoring, propping and needling for any Engineer-approved structural/load-bearing alteration, complete with design/method statement and removal after permanent works. | D39: LS | E39: 1 | F39: 1500000 | G39: =E39*F39 -> 1500000 | H39: Engineer PS | I39: PS-C7 | J39: Structural safety allowance | K39: Provisional; use only where structural Engineer confirms need.
A40: C | B40: C10 | C40: Core drilling / controlled builders-work openings in retained masonry/RCC for coordinated non-modular services and civil interfaces, including making good after installation. | D40: LS | E40: 1 | F40: 600000 | G40: =E40*F40 -> 600000 | H40: Engineer PS | I40: PS-C8 | J40: Coordination allowance | K40: Specialist structural approval required for RCC openings.
...

Sheet Ancillary Works - Reviewed
C1: MATARA HOSPITAL – ANCILLARY BUILDINGS / EXTENSION BOQ REVIEWED FOR CONSOLIDATION
A3: Section | B3: Item | C3: Description | D3: Unit | E3: Qty | G3: Rate (LKR) | H3: Amount | I3: Reviewed Amount | J3: Review Action | K3: Rate / Source Note | L3: Duplication Check | M3: Status | N3: Remarks
A4: C1. Demolition Work | C4: Demolition Work
A5: C1. Demolition Work | B5: C1.1 | C5: Demolish existing brick/block walls, foundations and obsolete plinths where required, including stacking serviceable material and disposal of debris. | D5: m³ | E5: 15 | G5: 1459 | H5: =E5*G5 -> 21885 | I5: 21885 | J5: RETAIN | K5: BSR Z07 / existing BOQ | L5: Site Work duplicates reviewed separately | M5: Source amount
A6: C1. Demolition Work | B6: C1.2 | C6: Demolish existing concrete floors/plinths/columns, slabs where required and clear debris from site. | D6: m³ | E6: 9 | G6: 10209 | H6: =E6*G6 -> 91881 | I6: 91881 | J6: RETAIN | K6: BSR Z02 / existing BOQ | L6: Site Work duplicates reviewed separately | M6: Source amount
A7: C1. Demolition Work | B7: C1.3 | C7: Removing roof tiles/cement fibre or asbestos roofing sheets and timber frame work, stacking serviceable materials and clearing debris away in two storied building. | D7: m2 | E7: 30 | G7: 550 | H7: =E7*G7 -> 16500
A8: C2. Excavation and Earth Work | C8: Excavation and earth work
A9: C2. Excavation and Earth Work | B9: C2.1 | C9: Removing top soil manually to a depth not exceeding 6" and removing all debris away from site up to a distance of 30'-0". (Removing top soil up to 2 sqrs.) | D9: m² | E9: 48 | G9: 80 | H9: =E9*G9 -> 3840 | I9: 3840 | J9: RETAIN | K9: BSR | L9: Site Work duplicates reviewed separately | M9: Source amount
A10: C2. Excavation and Earth Work | B10: C2.2 | C10: Manual excavation for column/walls including part backfill and disposal/stockpiling within site. | D10: m³ | E10: 30 | F10: =70*0.6*0.6+6*1.2*1.2*0.6 -> 30.384 | G10: 1889 | H10: =E10*G10 -> 56670 | I10: 15112 | J10: RETAIN | K10: BSR B07 / existing BOQ | L10: Site Work duplicates reviewed separately | M10: Source amount
A11: C2. Excavation and Earth Work | B11: C2.3 | C11: Random rubble (6"-9") masonry in cement sand mortar 1:5. | D11: m3 | E11: 30 | F11: =70*0.45*0.9 -> 28.35 | G11: 21797 | H11: =E11*G11 -> 653910 | I11: 261564 | J11: RETAIN | L11: Site Work duplicates reviewed separately | M11: Source amount
A12: C2. Excavation and Earth Work | B12: C2.4 | C12: Approved earth supplying, spreading & levelling manually, including watering in 225mm thick layers (measured on piled volume) & Compaction using a machine Rammer. Rate includes hire charges for the machine rammer. | D12: m³ | E12: 30 | F12: =100*0.3 -> 30 | G12: 4500 | H12: =E12*G12 -> 135000 | I12: 33740 | J12: RETAIN | K12: BSR B25 / existing BOQ | L12: Site Work duplicates reviewed separately | M12: Source amount
A13: C2. Excavation and Earth Work | B13: C2.6 | C13: Anti-termite treatment for the new construction with applying Biflexthrine 10Tc (Biflex ) or approved equivalent as per manufacturer's standards of application including horizontal & vertical barriers with 10 years warranty on application. (Measured on plinth area) | D13: m² | E13: 120 | F13: =70+30 -> 100 | G13: 850 | H13: =E13*G13 -> 102000 | I13: 40800 | J13: RETAIN | K13: BSR B41 / existing BOQ | L13: Site Work duplicates reviewed separately | M13: Source amount
A14: C3-Concrete Work | C14: Concrete Work
A15: C3-Concrete Work | B15: C3.1 | C15: Plain cement concrete 1:3:6 blinding under pad/wall foundations, 50mm thick. | D15: m² | E15: 55 | F15: =70*0.6+6*1.2*1.2 -> 50.64 | G15: 1431 | H15: =E15*G15 -> 78705 | I15: 89437.5 | J15: RETAIN | K15: BSR C02 / existing BOQ | L15: Site Work duplicates reviewed separately | M15: Source amount
A16: C3-Concrete Work | B16: C3.2 | C16: Grade 25 concrete to foundations. | D16: m³ | E16: 3 | F16: =6*1.2*1.2*0.3 -> 2.592 | G16: 34095 | H16: =E16*G16 -> 102285 | I16: 647805 | J16: RETAIN | K16: BSR C04 / existing BOQ | L16: Site Work duplicates reviewed separately | M16: Source amount
A17: C3-Concrete Work | B17: C3.3 | C17: Grade 25 concrete to columns up to roof level. | D17: m³ | E17: 3 | F17: =6*4*0.3*0.3 -> 2.16 | G17: 34095 | H17: =E17*G17 -> 102285 | I17: 184113 | J17: RETAIN | K17: BSR C04 / existing BOQ | L17: Site Work duplicates reviewed separately | M17: Source amount
A18: C3-Concrete Work | B18: C3.4 | C18: Grade 25 concrete to plinth/ground beams. | D18: m³ | E18: 3 | F18: =3*4*0.4*0.3+2*0.25*0.25*8 -> 2.44 | G18: 34095 | H18: =E18*G18 -> 102285 | I18: 508015.5 | J18: RETAIN | K18: BSR C04 / existing BOQ | L18: Site Work duplicates reviewed separately | M18: Source amount
A19: C3-Concrete Work | B19: C3.5 | C19: Gauge 750 polythene damp proof membrane with 6" laps laid under floors. | D19: m2 | E19: 100 | G19: 90 | H19: =E19*G19 -> 9000
A20: C3-Concrete Work | B20: C3.6 | C20: Grade 25 concrete in ground slab, including placing, compacting and finishing to receive floor finish. | D20: m³ | E20: 11 | F20: =8*4*0.1+70*0.1 -> 10.2 | G20: 34095 | H20: =E20*G20 -> 375045 | I20: 511425 | J20: RETAIN | K20: BSR C04 / existing BOQ | L20: Site Work duplicates reviewed separately | M20: Source amount
A21: C3-Concrete Work | B21: C3.7 | C21: Grade 25 concrete to roof beams, drain and parapet | D21: m³ | E21: 4 | F21: =3*4*0.4*0.3+2*0.25*0.25*8 -> 2.44 | G21: 35095 | H21: =E21*G21 -> 140380 | I21: 508015.5 | J21: RETAIN | K21: BSR C04 / existing BOQ | L21: Site Work duplicates reviewed separately | M21: Source amount
A22: C3-Concrete Work | B22: C3.8 | C22: Grade 25 concrete in roof slab, including placing, compacting and finishing to receive floor finish. | D22: m³ | E22: 5 | F22: =8*4*0.15 -> 4.8 | G22: 35095 | H22: =E22*G22 -> 175475 | I22: 531882 | J22: RETAIN | K22: BSR C04 / existing BOQ | L22: Site Work duplicates reviewed separately | M22: Source amount
A23: C3-Concrete Work | B23: C3.9 | C23: Curing of exposed reinforced concrete surfaces for 7 days. | D23: m²/day | E23: 1000 | G23: 32 | H23: =E23*G23 -> 32000 | I23: 32000 | J23: RETAIN | K23: BSR C37 / existing BOQ | L23: Site Work duplicates reviewed separately | M23: Source amount
A24: C3-Concrete Work | B24: C3.10 | C24: Formwork to sides of pad/wall foundations. | D24: m² | E24: 15 | F24: =1.2*4*6*0.3+70*0.05 -> 12.14 | G24: 1159 | H24: =E24*G24 -> 17385 | I24: 34770 | J24: RETAIN | K24: BSR D01 / existing BOQ | L24: Site Work duplicates reviewed separately | M24: Source amount
A25: C3-Concrete Work | B25: C3.11 | C25: Formwork to columns. | D25: m² | E25: 30 | F25: =6*4*0.3*4 -> 28.8 | G25: 3328 | H25: =E25*G25 -> 99840 | I25: 239616 | J25: RETAIN | K25: BSR D08 / existing BOQ | L25: Site Work duplicates reviewed separately | M25: Source amount
A26: C3-Concrete Work | B26: C3.12 | C26: Formwork to sides of plinth/ground beams. | D26: m² | E26: 25 | F26: =3*2*4*0.4+2*2*8*0.4 -> 22.4 | G26: 2047 | H26: =E26*G26 -> 51175 | I26: 92115 | J26: RETAIN | K26: BSR D03 / existing BOQ | L26: Site Work duplicates reviewed separately | M26: Source amount
A27: C3-Concrete Work | B27: C3.13 | C27: Formwork to sides and soffits of roof beams. | D27: m² | E27: 35 | F27: =F26+3*4*0.3+2*8*0.3 -> 30.8 | G27: 3868 | H27: =E27*G27 -> 135380 | I27: 264571.2 | J27: RETAIN | K27: BSR D06 / existing BOQ | L27: Site Work duplicates reviewed separately | M27: Source amount
A28: C3-Concrete Work | B28: C3.14 | C28: Formwork to soffit of roof slab | D28: m² | E28: 35 | F28: =4*8 -> 32 | G28: 3506 | H28: =E28*G28 -> 122710 | I28: 417214 | J28: RETAIN | K28: BSR D05 / existing BOQ | L28: Site Work duplicates reviewed separately | M28: Source amount
A29: C3-Concrete Work | B29: C3.15 | C29: Tor steel reinforcement to pad foundations, beams, coulumns and slab including cutting, bending, placing and tying. | D29: kg | E29: 4000 | F29: =22*140 -> 3080 | G29: 437 | H29: =E29*G29 -> 1748000 | I29: 546250 | J29: RETAIN | K29: BSR E04 / existing BOQ | L29: Site Work duplicates reviewed separately | M29: Source amount
A30: C3-Concrete Work | B30: C3.16 | C30: Supplying and laying in position of B.R.C mesh (6mm) - 4" x 4" | D30: m2 | E30: 120 | G30: 1485 | H30: =E30*G30 -> 178200 | I30: 546490.35 | J30: RETAIN | K30: BSR E04 proxy / existing BOQ | L30: Site Work duplicates reviewed separately | M30: Source amount
C31: Measonary Work
B32: C4.1 | C32: 3/4" thick D.P.C. in cement sand 1:3 finished with 2 coats of D.P.C. tar and blinded with sand. | D32: m2 | E32: =100*0.45 -> 45 | G32: 2487 | H32: =E32*G32 -> 111915
B33: C4.2 | C33: 150mm thick cement sand solid block wall (blocks confirming to S.L.S. 855 and subject to the approval of sample blocks) in cement and sand mortar 1:5 in ground floor. | D33: m² | E33: 175 | G33: 5890 | H33: =E33*G33 -> 1030750
B34: C4.3 | C34: 100mm thick cement sand solid block wall (blocks confirming to S.L.S.855 and subject to the approval of sample blocks) in cement and sand mortar 1:5 in ground floor. | D34: m² | E34: 25 | G34: 4190 | H34: =E34*G34 -> 104750 | I34: 1307280 | J34: RETAIN | K34: BSR G03 / existing BOQ | L34: Site Work duplicates reviewed separately | M34: Source amount
C35: Water proofing Work
B36: C5.1 | C36: Type - 1 - Internal Wet Areas without Exposure to Sunlight (Cementitious water proofing using Barralastic or approved equivalnt) Application of cementitious water proofing using Barralastic or approved equivalnt for internal wet areas such as toilet floors and walls where the surfaces are not directly exposed to sunlight and weathering. Rate shall include for cleaning the substrate and all other work as per manufacturer's specifications on application and shall include ponding test for a 300mm water height kept for a period of 48 hours for horizontal surfaces. | D36: m2 | E36: 20 | G36: 5587 | H36: =E36*G36 -> 111740
B37: C5.2 | C37: Type - 4 - Application of membrane type water proofing material for roofs) On roofs laying of Topseal 4 mm thick, Torch-on membrane or any other equivalent product marketed/installed by a specialist contractor registered at ICTAD under water proofing category including 1:3 cement,sand protective screed laid to slope. Rate shall include the formation of edges, torch welding and fixing metal strip on vertical walls at termination edges. | D37: m2 | E37: 40 | G37: 6135 | H37: =E37*G37 -> 245400
C38: Floor Finish
B39: C6.1 | C39: Rendering 1/2" thick in cement sand 1:3 finished smooth with cement slurry without colour pigment and expansion joints filled with construction expansion joint sealent including the cost for cleaning the joints prior application of construction expansion joint sealent by M/s Bitumix or approved equivalent. | D39: m2 | E39: 50 | G39: 1550 | H39: =E39*G39 -> 77500
B40: C6.2 | C40: Homogeneous porcelain semi - glazed floor tile 12" x 24" paving on tile adhesive (mortar) bedding and pointed with tile grout to match the tile. (Prime Cost of tile is Rs.627.00)-Floor | D40: m² | E40: 100 | G40: 6299 | H40: =E40*G40 -> 629900 | I40: 503920 | J40: RETAIN | L40: Site Work duplicates reviewed separately | M40: Source amount
B41: C6.3 | C41: Homogeneous porcelain semi - glazed floor tile 12" x 24" paving on tile adhesive (mortar) bedding and pointed with tile grout to match the tile. (Prime Cost of tile is Rs.627.00)-Bath Rooms | D41: m² | E41: 20 | G41: 6300 | H41: =E41*G41 -> 126000 | I41: 75600 | J41: RETAIN | L41: Site Work duplicates reviewed separately | M41: Source amount
...

Sheet Takeoff & Assumptions
A1: PRELIMINARY QUANTITY TAKEOFF & ASSUMPTIONS - ADDED RENOVATION WORKS
A3: Ref | B3: Parameter / Quantity | C3: Unit | D3: Preliminary Value | E3: Basis / Calculation | F3: Drawing / Source | G3: Action before Tender
A4: T01 | B4: OT1 area | C4: m² | D4: 43.403 | E4: 7.628 x 5.690 | F4: Modular source measurement / Room layout | G4: Verify by measured survey
A5: T02 | B5: OT2 area | C5: m² | D5: 31.573 | E5: 6.675 x 4.730 | F5: Modular source measurement / Room layout | G5: Verify by measured survey
A6: T03 | B6: OT3 area | C6: m² | D6: 61.514 | E6: 7.220 x 8.520 | F6: Modular source measurement / Room layout | G6: Verify by measured survey
A7: T04 | B7: OT4 area | C7: m² | D7: 51.417 | E7: 6.340 x 8.110 | F7: Modular source measurement / Room layout | G7: Verify by measured survey
A8: T05 | B8: Total four OT floor area | C8: m² | D8: 187.908 | E8: T01+T02+T03+T04 | F8: Modular source measurement | G8: Do not alter Modular OT BOQ quantity basis
A9: T06 | B9: Total scrub area | C9: m² | D9: 32.081 | E9: RN-03 + RN-06 + RN-08 | F9: Modular source measurement | G9: Do not alter Modular OT BOQ quantity basis
A10: T07 | B10: OT + scrub area used for preparatory substrate allowance | C10: m² | D10: 219.989 | E10: T05+T06 | F10: Modular source workbook | G10: Local patch/grind only; specialist flooring excluded
A11: T08 | B11: Approx. gross internal renovation floor area | C11: m² | D11: 1050 | E11: Drawing-scale/design allowance | F11: Drawings 004/007/011 | G11: Obtain full measured floor-area schedule
A12: T09 | B12: Approx. non-modular floor area | C12: m² | D12: 830 | E12: T08 - T07 | F12: Derived | G12: Split by room finish schedule before tender
A13: T10 | B13: Floor finish strip-out allowance | C13: m² | D13: 980 | E13: Most renovated floor area, excluding small retained zones | F13: Drawing 006 + renovation allowance | G13: Joint measure before demolition
A14: T11 | B14: Ceiling strip-out allowance | C14: m² | D14: 900 | E14: Approx. renovation ceiling extent | F14: Drawing 009 | G14: Survey ceiling/MEP conditions
A15: T12 | B15: 100 mm new block partition projected area | C15: m² | D15: 400 | E15: Preliminary wall takeoff | F15: Drawing 007 cyan new construction | G15: Measure wall lengths by thickness and height
... A29: T26 | B29: Existing redundant MEP service strip-out | C29: LS | D29: 1 | E29: Provisional multi-trade allowance for electrical/ELV, HVAC, plumbing/drainage and medical-gas lines affected by renovation. | F29: Site photographs / demolition coordination | G29: Undertake detailed service survey and isolation plan before demolition; measure major plant separately if encountered.
A30: CORE QUALIFICATIONS
A31: 1 | B31: All new quantities are preliminary allowances derived from visible drawing dimensions, room functions and scaled plan interpretation. They are not a substitute for a measured survey.
A32: 2 | B32: The existing beam layout is used as a structural control: do not remove or cut structural beams/columns/slabs without the Structural Engineer's written approval.
A33: 3 | B33: Load-bearing masonry demolition is intentionally set to zero. If later required, measure masonry separately and price temporary works/propping/needling to the approved method.
A34: 4 | B34: The unchanged Modular OT package already includes modular walls/ceilings, conductive flooring, hermetic OT doors, OT fixed fittings, LAF/HVAC package, electrical/medical-gas interfaces and validation as scheduled. Added works avoid intentional duplication.
A35: 5 | B35: The unchanged Site Works BOQ remains exactly as supplied and is reproduced in the 'Site Works - Unchanged' sheet.
A36: 6 | B36: New building electrical, ELV, plumbing, medical-gas distribution and HVAC installations outside the unchanged Modular OT package remain excluded except for builders-work interfaces. Removal/strip-out of redundant existing service lines and associated safe isolation/capping are included under Section I of the Added Renovation BOQ.

Sheet Rates & Basis
A1: RATE REGISTER & PRICING BASIS - ADDED RENOVATION WORKS
A3: Rate Ref. | B3: Description / Application | C3: Unit | D3: Base / Source Rate | E3: Markup | F3: Applied Rate (LKR) | G3: Rate Type | H3: Source / Page | I3: Source URL / File | J3: Qualification
A4: DM41 | B4: Remove & stack aluminium door/window with frame and make good | C4: m² | D4: 405 | E4: 0 | F4: 405 | G4: Matara BSR 2026 | H4: DM 4/4 | I4: https://www.cs.sp.gov.lk/css/csw/rates/bsr_matara_2026.pdf | J4: Direct BSR; measure overall area.
A5: DM43 | B5: Carefully remove aluminium partitions at joints for reuse/stack | C5: m² | D5: 369 | E5: 0 | F5: 369 | G5: Matara BSR 2026 - qualified | H5: DM 4/4 | I5: https://www.cs.sp.gov.lk/css/csw/rates/bsr_matara_2026.pdf | J5: Used as closest rate for aluminium glazed partition/curtain wall removal.
A6: DM08 | B6: Demolish brickwork in cement and clear debris | C6: m³ | D6: 2000 | E6: 0 | F6: 2000 | G6: Matara BSR 2026 - qualified | H6: DM 1/4 | I6: https://www.cs.sp.gov.lk/css/csw/rates/bsr_matara_2026.pdf | J6: Does not include engineered shoring/needling.
A7: DM19 | B7: Demolish tiles with tile bed | C7: m² | D7: 770 | E7: 0 | F7: 770 | G7: Matara BSR 2026 | H7: DM 1/4-2/4 | I7: https://www.cs.sp.gov.lk/css/csw/rates/bsr_matara_2026.pdf | J7: Applied to floor finish strip-out.
A8: B40 | B8: Dispose debris by tractor trailer up to 3 km | C8: Load | D8: 4207 | E8: 0 | F8: 4207 | G8: Existing unchanged Site BOQ BSR | H8: B40 | I8: Matara_OT_Site_Works_Landscaping_BOQ(1).xlsx | J8: Reused only as disposal benchmark; source Site BOQ itself remains unchanged.
A9: CT54 | B9: Grade 25 concrete; reinforcement/formwork separate | C9: m³ | D9: 32300 | E9: 0 | F9: 32300 | G9: Matara BSR 2026 | H9: CT 8/11 | I9: https://www.cs.sp.gov.lk/css/csw/rates/bsr_matara_2026.pdf | J9: Generic Grade 25 rate for local concrete.
A10: RF02 | B10: Reinforcement cut/bend/fix | C10: kg | D10: 494 | E10: 0 | F10: 494 | G10: Matara BSR 2026 - qualified | H10: RF 1/1 | I10: https://www.cs.sp.gov.lk/css/csw/rates/bsr_matara_2026.pdf | J10: Split by level/grade when final details are issued.
A11: FW19 | B11: Plywood formwork to beam sides/soffits | C11: m² | D11: 4070 | E11: 0 | F11: 4070 | G11: Matara BSR 2026 - qualified | H11: FW 7/8 | I11: https://www.cs.sp.gov.lk/css/csw/rates/bsr_matara_2026.pdf | J11: Budget proxy for local formwork categories.
A12: DER-L100 | B12: Derived reinforced Grade 25 precast lintel 100x150 mm | C12: m | D12: 2650.8136 | E12: 0 | F12: 2650.8136 | G12: Derived Matara BSR 2026 | H12: CT44 + RF02 | I12: https://www.cs.sp.gov.lk/css/csw/rates/bsr_matara_2026.pdf | J12: Budgetary; final bar schedule/bearing length to structural details.
A13: DER-L150 | B13: Derived reinforced Grade 25 precast lintel 150x150 mm | C13: m | D13: 3520.3051 | E13: 0 | F13: 3520.3051 | G13: Derived Matara BSR 2026 | H13: CT44 + RF02 | I13: https://www.cs.sp.gov.lk/css/csw/rates/bsr_matara_2026.pdf | J13: Budgetary derived rate.
A14: CB01 | B14: 100 mm cement solid block wall in 1:5 mortar | C14: m² | D14: 3000 | E14: 0 | F14: 3000 | G14: Matara BSR 2026 | H14: CB 1/1 | I14: https://www.cs.sp.gov.lk/css/csw/rates/bsr_matara_2026.pdf | J14: Non-load-bearing.
A15: DER-CB6 | B15: 150 mm cement block wall derived from CB01 x1.50 | C15: m² | D15: 4500 | E15: 0 | F15: 4500 | G15: Derived Matara BSR 2026 | H15: CB01 x 1.50 | I15: https://www.cs.sp.gov.lk/css/csw/rates/bsr_matara_2026.pdf | J15: Obtain approval before final tender use.
... A26: MOD-R2 | B26: Clinical vinyl floor budget benchmark | C26: m² | D26: 13500 | E26: 0 | F26: 13500 | G26: Existing Modular OT market benchmark | H26: Rate Basis R2 / scrub application | I26: F-Matara_Modular_OT_BOQ_Market_Prices.xlsx | J26: Applied only outside specialist modular scope; obtain written supplier quote.
A27: PS | B27: Engineer provisional sums / market allowances | C27: Various | G27: Engineer PS / market allowance | H27: See BOQ item | I27: N/A | J27: Replace with approved quotation/rate analysis before tender where material to total.
A28: PS-I1 | B28: Existing equipment inventory/tagging and relocation schedule | C28: LS | D28: 250000 | E28: 0 | F28: 250000 | G28: Engineer PS | H28: Section I | I28: Site photographs / Employer direction | J28: Replace with agreed method/resource build-up if required.
A29: PS-I2 | B29: Relocation of loose/semi-fixed hospital furniture and non-specialist equipment | C29: LS | D29: 1000000 | E29: 0 | F29: 1000000 | G29: Engineer PS | H29: Section I | I29: Site photographs / Employer direction | J29: Provisional handling/protection allowance; final scope by inventory.
A30: PS-I3 | B30: Specialist biomedical/OEM attendance for sensitive/fixed medical equipment relocation | C30: PS | D30: 1500000 | E30: 0 | F30: 1500000 | G30: Engineer PS / provisional sum | H30: Section I | I30: Site photographs | J30: Expenditure only on written instruction and supported by quotations/invoices.
A31: PS-I4 | B31: Redundant electrical and ELV service-line strip-out | C31: LS | D31: 900000 | E31: 0 | F31: 900000 | G31: Engineer PS | H31: Section I | I31: Existing MEP / demolition coordination | J31: Safe isolation/testing by licensed personnel; new installation excluded.
A32: PS-I5 | B32: Redundant HVAC duct/air-distribution service-line strip-out | C32: LS | D32: 900000 | E32: 0 | F32: 900000 | G32: Engineer PS | H32: Section I | I32: Site photographs / ceiling zones | J32: Major plant excluded unless separately instructed.
A33: PS-I6 | B33: Redundant plumbing/water/drainage service-line strip-out | C33: LS | D33: 600000 | E33: 0 | F33: 600000 | G33: Engineer PS | H33: Section I | I33: Wet areas / existing services | J33: Includes drain down, capping and temporary seals only.
A34: PS-I7 | B34: Medical-gas line isolation/removal/capping/testing by approved specialist | C34: LS | D34: 600000 | E34: 0 | F34: 600000 | G34: Engineer PS / specialist allowance | H34: Section I | I34: Existing clinical services | J34: Permit-to-work, purge and certification mandatory.

Sheet Site Works - Unchanged
A1: PRELIMINARY BOQ & ENGINEER'S ESTIMATE - SITE WORKS / LANDSCAPING | O1: Source status | P1: UNCHANGED reproduction
A2: Improvement of MEP Services and Renovation of Theater Complex - Periphery Site Works | O2: Source file | P2: Matara_OT_Site_Works_Landscaping_BOQ(1).xlsx
A3: Preliminary quantity takeoff from the 1:200 development-boundary plan and site photographs. Final BOQ quantities shall be remeasured after topographic levels, demolition survey and approved landscape layout. | O3: Source total (LKR) | P3: 4798506.9
O4: Instruction | P4: Do not modify source site-work scope/rates/quantities in this consolidated estimate.
A5: Item | B5: Section | C5: Item | D5: Description | E5: BSR / Basis | F5: Unit | G5: Qty | H5: Rate (LKR) | I5: Amount (LKR) | J5: Status | K5: Drawing/Photo Basis | L5: Inclusion / Qualification | M5: Remarks
B6: A1.Preliminaries
A7: 1 | B7: A1.Preliminaries | C7: A1.1 | D7: Protection to live hospital, barricading, dust/noise control, temporary access and housekeeping | E7: Engineer PS | F7: Item | G7: 1 | H7: 150000 | I7: =IF(G7*H7<>0,G7*H7,"") -> 150000 | J7: PS | K7: Site condition | L7: Complete for external works adjoining occupied hospital
A8: 2 | B8: A1.Preliminaries | C8: A1.2 | D8: Setting out, levels and site survey for external works | E8: Engineer PS | F8: Item | G8: 1 | H8: 175000 | I8: =IF(G8*H8<>0,G8*H8,"") -> 175000 | J8: PS | K8: Site plan 1:200 | L8: Establish final grading and drain falls
A9: Subtotal - A. Preliminaries | I9: =SUM(I7:I8) -> 325000
I10: =IF(G10*H10<>0,G10*H10,"")
A11: 3 | B11: A2. Clearance & Demolition | C11: A2.1 | D11: Clear site vegetation, bushes, shrubs and rubbish | E11: B01 | F11: m² | G11: 650 | H11: 86 | I11: =IF(G11*H11<>0,G11*H11,"") -> 55900 | J11: BSR | K11: Scaled plan + photos | L11: Entire preliminary external site-work area
A12: 4 | B12: A2. Clearance & Demolition | C12: A2.2 | D12: Remove banana/small trees including roots | E12: Engineer PS | F12: LS | G12: 1 | H12: 25000 | I12: =IF(G12*H12<>0,G12*H12,"") -> 25000 | J12: PS | K12: Site photos | L12: Large mature trees excluded
A13: 5 | B13: A2. Clearance & Demolition | C13: A2.3 | D13: Demolish existing RCC canopy / covered walkway and supports | E13: Z01 proxy | F13: m³ | G13: 8 | H13: 12000 | I13: =IF(G13*H13<>0,G13*H13,"") -> 96000 | J13: BSR proxy | K13: Site photo | L13: Selective demolition only where conflicting with works
A14: 6 | B14: A2. Clearance & Demolition | C14: A2.4 | D14: Remove existing corrugated lean-to / roof and light frame | E14: Z28 proxy | F14: m² | G14: 45 | H14: 357 | I14: =IF(G14*H14<>0,G14*H14,"") -> 16065 | J14: BSR proxy | K14: Site photos | L14: Material survey required; ACM, if present, by approved specialist method
A15: 7 | B15: A2. Clearance & Demolition | C15: A2.5 | D15: Break out existing concrete hardstanding | E15: Z02 | F15: m³ | G15: 8 | H15: 10209 | I15: =IF(G15*H15<>0,G15*H15,"") -> 81672 | J15: BSR | K15: Photo provisional | L15: Quantity derived from 80m² x 0.10m average
A16: 8 | B16: A2. Clearance & Demolition | C16: A2.6 | D16: Demolish existing drain sections where replacement is required | E16: Z10 | F16: m | G16: 50 | H16: 262 | I16: =IF(G16*H16<>0,G16*H16,"") -> 13100 | J16: BSR | K16: Condition allowance | L16: Only defective/conflicting sections
A17: 9 | B17: A2. Clearance & Demolition | C17: A2.7 | D17: Dispose demolition/clearance debris by tractor trailer, up to 3km | E17: B40 | F17: Load | G17: 20 | H17: 4207 | I17: =IF(G17*H17<>0,G17*H17,"") -> 84140 | J17: BSR | K17: Provisional | L17: Approved disposal point to be confirmed
A18: Subtotal - B. Clearance & Demolition | I18: =SUM(I11:I17) -> 371877
A20: 10 | B20: A3. Earthworks & Grading | C20: A3.1 | D20: Supply approved earth for filling/regrading | E20: B26 | F20: m³ | G20: 30 | H20: 3177 | I20: =G20*H20 -> 95310 | J20: BSR | K20: Provisional levels | L20: Final from level survey
A21: 11 | B21: A3. Earthworks & Grading | C21: A3.2 | D21: Spread, level, water and compact approved earth | E21: B32 | F21: m³ | G21: 30 | H21: 444 | I21: =G21*H21 -> 13320 | J21: BSR | K21: Provisional levels | L21: To falls away from building and toward drains
A22: Subtotal - C. Earthworks & Grading | I22: =SUM(I20:I21) -> 108630
B23: Repair | D23: Repair existing drains
A24: 12 | B24: A4. Surface Drainage | C24: A4.1 | D24: Clean, desilt and flush existing perimeter drains | E24: Engineer PS | F24: m | G24: 100 | H24: 550 | I24: =G24*H24 -> 55000 | J24: PS | K24: Green drain alignment | L24: Protect connections and maintain drainage during works
A25: 13 | B25: A4. Surface Drainage | C25: A4.2 | D25: Repair / construct small concrete drains | E25: C23 proxy | F25: m | G25: 20 | H25: 3219 | I25: =G25*H25 -> 64380 | J25: BSR proxy | K25: Condition allowance | L25: Final section/cover details to be coordinated
B26: A4. Surface Drainage
B27: A4. Surface Drainage | C27: A4.3 | D27: Manual Excavation for column, surface drainage in hard dense soil (except rock requiring blasting) up to 5'-0" depth, part return fill in and ram and surplus deposited within site as directed. (Transport of material to be paid seperately) | F27: m³ | G27: =40*0.6*1 -> 24 | H27: 2371 | I27: =G27*H27 -> 56904
B28: A4. Surface Drainage | C28: A4.4 | D28: Cement concrete 1:3:6 (1") laid to a thickness of 2" under Drainage, including placing in position,compacting. | F28: m2 | G28: =40*0.75 -> 30 | H28: 1490 | I28: =G28*H28 -> 44700
C29: A4.5 | D29: Grade 25 concrete in foundation, wall in Drain construction | F29: m3 | G29: =40*1.8*0.15 -> 10.8 | H29: 34095 | I29: =G29*H29 -> 368226
C30: A4.6 | D30: Tor steel reinforcement to base, wall and cover of surface drainage work etc.. bent to shape, laid in position and tied with 16 B.W.G. Aneal binding wire in second floor. (Laps should be measured as per the drawings ). | F30: kg | G30: =G29*120 -> 1296 | H30: 459 | I30: =G30*H30 -> 594864
C31: A4.7 | D31: formwork | F31: m2 | G31: 120 | H31: 2790 | I31: =G31*H31 -> 334800
C32: A4.8 | D32: Supply, manufacture and place heavy-duty precast reinforced concrete cover slabs, minimum 125 mm thick, Grade 25 concrete, over surface drainage channels, of approved panel sizes, reinforced to withstand the specified vehicular/loading conditions, complete with high-yield reinforcement, moulds/formwork, lifting hooks/recesses where required, chamfered edges, curing, transportation, handling, bedding/seating in cement mortar, alignment and levelling, cutting and adjustment at ends and junctions, and all labour, materials, plant and incidental works necessary to provide a complete installation, all in accordance with approved drawings and Engineer's instructions. | F32: m2 | G32: 25 | H32: 35000 | I32: =G32*H32 -> 875000
C33: A4.9 | D33: Supply, fabricate and place precast reinforced concrete light-duty cover slabs over existing surface drainage, minimum 100 mm thick, Grade 25 concrete, in manageable panel sizes to suit the existing drain, reinforced with approved high-yield steel reinforcement, complete with formwork/moulds, lifting arrangements where required, chamfered edges, curing, transportation, handling, placing, levelling and proper seating over the existing drain walls; including minor preparation and making good of existing drain edges, cement mortar bedding where necessary, and all labour, materials, plant and incidental works required for a complete installation, all to the Engineer's approval. | F33: m2 | G33: =70*0.7 -> 49 | H33: 18000 | I33: =G33*H33 -> 882000
A34: Subtotal - D. Surface Drainage | I34: =SUM(I24:I33) -> 3275874
A36: 14 | B36: E. Hard Landscape | C36: A5.1 | D36: 60mm coloured interlocking paving blocks to pedestrian/service areas | E36: AA26 | F36: m² | G36: 700 | H36: 5136 | I36: =H36*G36 -> 3595200 | J36: BSR | K36: Design allocation | L36: Existing road and connecting corridors excluded
A37: 15 | B37: E. Hard Landscape | C37: A5.2 | D37: Precast concrete curb / edging | E37: AA31 | F37: m | G37: 90 | H37: 2713 | I37: =H37*G37 -> 244170 | J37: BSR | K37: Design allocation | L37: At turf/paving and landscape edges
A39: Subtotal - E. Hard Landscape | I39: =SUM(I36:I38) -> 3839370
A41: 16 | B41: F. Soft Landscape | C41: A6.1 | D41: Prepare turf area with 150mm top vegetable soil / coir mixture | E41: AA01 | F41: m² | G41: 150 | H41: 2390 | I41: =H41*G41 -> 358500 | J41: BSR | K41: Design allocation | L41: Includes root/gravel removal and final grading
A42: 17 | B42: F. Soft Landscape | C42: A6.2 | D42: Supply and lay buffalo grass turf | E42: AA02 | F42: m² | G42: 150 | H42: 624 | I42: =H42*G42 -> 93600 | J42: BSR | K42: Design allocation | L42: Includes establishment maintenance stated in BSR
A43: 18 | B43: F. Soft Landscape | C43: A6.3 | D43: Prepare ornamental planting beds incl. topsoil, compost, cultivation and mulch | E43: Engineer PS | F43: m² | G43: 40 | H43: 2400 | I43: =H43*G43 -> 96000 | J43: PS | K43: Design allocation | L43: Final landscape plan required
A44: 19 | B44: F. Soft Landscape | C44: A6.4 | D44: Supply and plant approved shrubs / groundcovers | E44: Engineer PS | F44: Nr | G44: 15 | H44: 1100 | I44: =H44*G44 -> 16500 | J44: PS | K44: Design allocation | L44: Low-maintenance species suited to hospital environment
...

Sheet Modular OT - Unchanged
A1: Item No. | B1: Section | C1: Description | D1: Scope / technical basis | E1: Unit | F1: Quantity | G1: Market Rate (LKR) | H1: Amount (LKR) | I1: Rate basis | J1: Source URL / note
A2: A1 | B2: A - Modular envelope | C2: Modular OT wall panels with support frame and sealed joints | D2: Hygienic antibacterial coated 1.2mm metal/SS304 or approved equivalent; includes sub-frame, sealant and flush service coordination | E2: m² | F2: 345.9519 | G2: 48000 | H2: =F2*G2 -> 16605691 | I2: Direct market benchmark: modular OT wall panel INR 900/sq.ft converted and uplifted for import/local installation | J2: https://www.vkcleanrooms.co.in/modular-operation-theater.html
A3: A2 | B3: A - Modular envelope | C3: Airtight modular ceiling panels with support frame | D3: Hygienic removable/accessible sealed ceiling panels coordinated with LAF, lights and pendants | E3: m² | F3: 197 | G3: 48000 | H3: =F3*G3 -> 9456000 | I3: Applied same benchmark as modular OT panel with ceiling subframe/access uplift | J3: https://www.vkcleanrooms.co.in/modular-operation-theater.html
A4: A3 | B4: A - Modular envelope | C4: Scrub area wall panels and support frame | D4: Associated RN-03/RN-06/RN-08 scrub rooms; same hygienic panel system, subject to confirmation | E4: m² | F4: 131.1912 | G4: 42000 | H4: =F4*G4 -> 5510030.4 | I4: Budget rate derived from modular panel benchmark, lower complexity than OT rooms | J4: https://www.vkcleanrooms.co.in/modular-operation-theater.html
A5: A4 | B5: A - Modular envelope | C5: Scrub area ceiling panels | D5: Associated scrub-room hygienic ceilings | E5: m² | F5: 33.685313 | G5: 42000 | H5: =F5*G5 -> 1414783.1 | I5: Budget rate derived from modular panel benchmark | J5: https://www.vkcleanrooms.co.in/modular-operation-theater.html
A6: A5 | B6: A - Modular envelope | C6: 2mm conductive / anti-static vinyl flooring to OT rooms | D6: Self levelling screed, copper grid, conductive adhesive, heat welding and 100mm coved skirting interface | E6: m² | F6: 197.30326 | G6: 15000 | H6: =F6*G6 -> 2959549 | I6: Market benchmark INR 95/sq.ft anti-static vinyl plus adhesive, screed, copper grid and installation uplift | J6: https://www.tradeindia.com/products/hospital-vinyl-flooring-anti-static-homogeneous-conductive-vinyl-flooring-i-c8716784.html
A7: A6 | B7: A - Modular envelope | C7: Clinical vinyl flooring to scrub areas | D7: Same installed flooring standard, non-slip/cleanable with coving | E7: m² | F7: 33.685313 | G7: 13500 | H7: =F7*G7 -> 454751.72 | I7: Derived from anti-static vinyl benchmark with lower copper-grid allowance | J7: https://www.tradeindia.com/products/hospital-vinyl-flooring-anti-static-homogeneous-conductive-vinyl-flooring-i-c8716784.html
A8: A7 | B8: A - Modular envelope | C8: Coved skirting, internal coves, trims, sealants and penetration finishing | D8: Allowance for additional coving/trim around corners, columns, doors, and service penetrations | E8: LS | F8: 1 | G8: 1800000 | H8: =F8*G8 -> 1800000 | I8: Budget allowance based on measured perimeter and detailed trim complexity | J8: Measured allowance
A9: A8 | B9: A - Modular envelope | C9: Secondary steel/support framework for LAF, surgical lights, pendants and ceiling equipment | D9: Independent support frames, anchor bolts, coordination and load certification; excludes major structural strengthening | E9: No | F9: 4 | G9: 850000 | H9: =F9*G9 -> 3400000 | I9: Budget allowance; final rate to follow structural design and load calculations | J9: Provisional
A10: B1 | B10: B - Doors & dampers | C10: Automatic hermetically sealed theatre door 1500x2100x50mm | D10: Japan/equivalent machine set, touchless switches x2, sensors, manual release and trolley protection | E10: No | F10: 4 | G10: 1200000 | H10: =F10*G10 -> 4800000 | I10: Market benchmark: hermetic OT sliding door INR 185,000-268,000 plus import/local installation uplift | J10: https://www.hospitaldoors.in/operation-theater-doors.html
A11: B2 | B11: B - Doors & dampers | C11: Hermetic single swing/rear theatre door 1500x2100x50mm | D11: Hygienic door leaf/frame with vision panel, seals and hardware | E11: No | F11: 2 | G11: 480000 | H11: =F11*G11 -> 960000 | I11: Budget rate benchmarked from hermetic hospital door market listings | J11: https://www.hospitaldoors.in/hermetic-doors.html
B12: B - Doors & dampers | C12: Hermatic double swing door to scrub Area | F12: 3 | G12: 480000 | H12: =F12*G12 -> 1440000
A13: B3 | B13: B - Doors & dampers | C13: Pressure relief damper SS 350x140mm | D13: Stainless steel pressure relief damper, balancing and cleanable grille | E13: No | F13: 12 | G13: 95000 | H13: =F13*G13 -> 1140000 | I13: Market sources range from INR 12,000 to INR 84,900; selected mid budget installed rate | J13: https://www.jkenggindia.com/operation-theater-equipment.html
A14: B4 | B14: B - Doors & dampers | C14: Pass-through hatch box 600x600x600mm | D14: SS304 manual pass-through window with UV light and interlock where required | E14: No | F14: 4 | G14: 350000 | H14: =F14*G14 -> 1400000 | I14: Budgetary market allowance; exact rate depends on interlock/UV/control specification | J14: Provisional
A15: B5 | B15: B - Doors & dampers | C15: Air return inlet / fluff separator with filter | D15: Flush SS304 air return inlet, removable filter/fluff separator and volume damper | E15: No | F15: 16 | G15: 95000 | H15: =F15*G15 -> 1520000 | I15: Budgetary rate derived from pressure damper/fluff separator components | J15: Provisional
A16: C1 | B16: C - Fixed OT fittings | C16: Three-bay scrub sink with sensor/knee controls | D16: SS316 body/SS304 casing, infrared taps, soap dispensers, drainage connections | E16: No | F16: 3 | G16: 750000 | H16: =F16*G16 -> 2250000 | I16: Scrub sink market range INR 30,000-100,000; uplift for 3-bay SS316/sensor/local install | J16: https://www.tradeindia.com/products/stainless-steel-304-surgical-scrub-sink-6937771.html
A17: C2 | B17: C - Fixed OT fittings | C17: LED backlight X-ray viewer, 2 bay, approx. 1000x625x102mm | D17: Dimmable LED viewer with shutter, flush mounting and wiring | E17: No | F17: 4 | G17: 250000 | H17: =F17*G17 -> 1000000 | I17: Market LED X-ray viewer prices vary from low single/double units to INR 79,000 multi-screen; selected 2-bay installed allowance | J17: https://www.tradeindia.com/manufacturers/x-ray-viewer.html
A18: C3 | B18: C - Fixed OT fittings | C18: SS storage cabinets 900x350x1800mm | D18: Flush/hygienic SS304 storage cabinets; 3 per theatre | E18: No | F18: 12 | G18: 325000 | H18: =F18*G18 -> 3900000 | I18: Budgetary fabricated SS304 cabinet rate | J18: Provisional
A19: C4 | B19: C - Fixed OT fittings | C19: SS writing table / operating list board with light | D19: Approx. 900W x 450H x 280D, hygienic surface and concealed fixing | E19: No | F19: 4 | G19: 175000 | H19: =F19*G19 -> 700000 | I19: Budgetary fabricated SS rate | J19: Provisional
A20: C5 | B20: C - Fixed OT fittings | C20: Flush OT control panel | D20: Clock, timer, gas alarm interface, intercom/telephone, temperature/RH display, lighting controls and HEPA status | E20: No | F20: 4 | G20: 850000 | H20: =F20*G20 -> 3400000 | I20: Market control panel listings INR 90,000 to 500,000; selected mid/high healthcare integrated rate | J20: https://www.bio-xhealthcare.com/surgeon-control-panel.html
A21: C6 | B21: C - Fixed OT fittings | C21: Air-sealed cleanroom lighting box 1200x300x38mm | D21: Airtight cleanroom/OT LED luminaire, dimming interface and below-access maintenance | E21: No | F21: 40 | G21: 85000 | H21: =F21*G21 -> 3400000 | I21: Cleanroom light market references converted and uplifted for sealed OT luminaire | J21: https://denphongsach.com/en/post/latest-price-list-of-clean-room-lights-used-in-medical-clean-rooms-76.htm
A22: C7 | B22: C - Fixed OT fittings | C22: Ceiling-mounted double-dome LED surgical light | D22: Major surgery double dome LED light with ceiling suspension, controls and installation | E22: No | F22: 4 | G22: 1500000 | H22: =F22*G22 -> 6000000 | I22: Double-dome OT light market range INR 53,800-495,800; selected hospital-grade budget rate | J22: https://www.hospitalstore.com/ot-lights/double-dome/
A23: C8 | B23: C - Fixed OT fittings | C23: Single-arm anaesthetist pendant | D23: Medical gas/electrical/data pendant with outlets as uploaded quotation, arm and suspension | E23: No | F23: 4 | G23: 1600000 | H23: =F23*G23 -> 6400000 | I23: Pendant market references from INR 58,000 to 500,000; selected higher specification installed rate | J23: https://www.dnhshealthcaredevicesprivatelimited.com/single-arm-surgical-pendant-7535161.html
A24: C9 | B24: C - Fixed OT fittings | C24: Surgical pendant / monitor support arm allowance | D24: Ceiling-mounted surgical services/monitor arm, if required by final clinical equipment layout | E24: No | F24: 4 | G24: 1200000 | H24: =F24*G24 -> 4800000 | I24: Provisional allowance pending final clinical layout | J24: Provisional
... A38: F3 | B38: F - T&C / deliverables | C38: Mobilisation, freight, local handling, protection and demobilisation | D38: Import/local transport, unloading, storage, site protection, cleaning and demobilisation | E38: LS | F38: 1 | G38: 4200000 | H38: =F38*G38 -> 4200000 | I38: Budgetary logistics allowance for imported/modular packages | J38: Provisional
A40: Total before contingency and VAT | H40: =SUM(H2:H38) -> 1.4907081e+08

Sheet Source Notes
A1: SOURCE DOCUMENTS, SCOPE CONTROLS & EXCLUSIONS
A3: Source | B3: Reference / File | C3: How Used | D3: Important Control
A4: Site Works BOQ | B4: Matara_OT_Site_Works_Landscaping_BOQ(1).xlsx | C4: Copied unchanged; exact total retained in Summary. | D4: No changes to scope, quantities, rates or contingency.
A5: Modular OT BOQ | B5: F-Matara_Modular_OT_BOQ_Market_Prices.xlsx | C5: Copied unchanged; exact direct and VAT-inclusive totals retained. | D5: No changes to existing 35-line specialist modular package.
A6: Existing plan | B6: 004-Existing G.Floor plan.pdf / DGHM-P2-A-004 | C6: Existing layout and refurbishment boundary context. | D6: Remeasure final dimensions on site.
A7: Beam layout | B7: 005-Existing 1st floor beam layout.pdf / DGHM-P2-A-005 | C7: Structural frame control for demolition and openings. | D7: No structural demolition/cutting without Structural Engineer approval.
A8: Demolition plan | B8: 006-Existing G.floor Demolition.pdf / DGHM-P2-A-006 | C8: Primary selective demolition basis. | D8: Red-highlight demolition is interpreted as mainly partition/fit-out work; verify thickness/material.
A9: New construction | B9: 007-G.Floor New construction.pdf / DGHM-P2-A-007 | C9: New wall/partition and making-good basis. | D9: Partition areas are provisional until detailed room-by-room takeoff.
A10: Door layout | B10: 008-G.Floor Doors.pdf / DGHM-P2-A-008 | C10: Door allowance basis. | D10: 62 door tags identified; 8 modular hermetic OT doors are already in Modular OT BOQ, leaving 54 provisional non-modular doors.
